+++
title = "エラーハンドリング"
weight = 1
+++

## 概要
NextJS(App router) + TypeScriptでAPI実装する際の
エラーハンドリングを検討します。  
※試行段階のため間違っている内容が含まれる可能性が多分にあります  
※そもそも外部のwebhookやAPIなどを呼び出すわけではない場合、  
　データアクセスではroute handlerではなくサーバーコンポーネントで実装するべきなようです  
　（NextJSでよくある10の間違いのNG1参照）  

## 実現したい内容
- ①エラー発生時の処理を一元的に管理する
- ②関数が何のエラー型を返すのかわかるようにする
- ③想定外のエラー発生時、エラーレスポンスを返す
    - APIごとに記述しなくて良いようにする
    - エラーを想定内エラー（業務エラー）と想定外エラー（システムエラー）に分け、  
      レスポンスを変える

## 懸念点
- TypeScriptではjavaのthrowsのような記述ができない
- TypeScriptではcatchした例外がany型として扱われる
  ※TypeScript 4.4からはunknown型として扱える
- JavaのSpring Frameworkでいうアノテーションの@ExceptionHandlerのような機能はない

## 試行
### ①エラー発生時の処理を一元的に管理する
NextJSでroute handlerを利用する際に呼び出される  
app/api/●●/route.tsで、関数をラッピングする  
※authenticate内にtry catchを記述し、authenticateに引数として渡した関数をそのtry内で実行する。  
　catchした場合は500エラーを返却する。  

**app/api/comments/route.ts**
``` typescript
import { authenticate } from "../common/authentication";
import { resultToResponse } from "../common/errorHandling";
import { createComment, deleteComment, getComments } from "./comments";
export const dynamic = "force-dynamic"; // static by default, unless reading the request

export const GET = authenticate(resultToResponse(getComments));
export const POST = authenticate(resultToResponse(createComment));
export const DELETE = authenticate(resultToResponse(deleteComment));
```

api/common/authentication
``` typescript
import { NextRequest, NextResponse } from "next/server";
import { decrypt } from "@/app/lib/sessionAuth";

// API呼び出し時に認証チェックを行うwrapper関数
export const authenticate = (
  handler: (req: NextRequest) => Promise<NextResponse>
): ((req: NextRequest) => Promise<NextResponse>) => {
  return async (req: NextRequest) => {
    try {
      // セッションをクッキーから取得
      const session = req.cookies.get("session")?.value;

      if (!session) {
        return NextResponse.json({ error: "invalid token" }, { status: 401 });
      }

      // セッションの復号処理
      const sessionDecrypted = await decrypt(session);

      if (!sessionDecrypted) {
        return NextResponse.json({ error: "invalid token" }, { status: 401 });
      }

      // セッションが有効であれば、元のハンドラを呼び出す
      return handler(req);
    } catch {
      return NextResponse.json(
        {
          error: "システムエラーが発生しました",
        },
        { status: 500 }
      );
    }
  };
};
```
### - ②関数が何のエラー型を返すのかわかるようにする
typescriptではjavaのthrowsなどがないため、  
そのメソッドが何のエラーを返しうるのか記述することができない。
``` typescript
// 何のエラーが返されるのかわからない
function doSomething(data: SomethingArgType): SomethingReturnType{
  const ret: SomethingReturnType = ... //何かの処理
  return ret;
}
```
そのためメソッドの返り値をSuccessとFailureの値をとりうるResult型として定義し、 
ジェネリクスで成功時に返す値とエラーを指定するようにする。

``` typescript
// 
function doSomething(data: SomethingArgType): Result<SomethingReturnType, SomethingError>{
  const ret: SomethingReturnType = ... //何かの処理
  if (!ret) {
    return new Failure(new SomethingError("ret", ret), "system");
  }
  return new Success(ret);
}
```

Result型とFalure型を以下のように定義する
``` typescript
import { NextRequest, NextResponse } from "next/server";

export type Result<T, E extends Error> = Success<T, E> | Failure<T, E>;
export type ErrorType = "business" | "system";
export class NoErrorDefined extends Error {
  constructor() {
    super("No error");
    Object.setPrototypeOf(this, NoErrorDefined.prototype);
  }
}

export class Success<T, E extends Error> {
  constructor(readonly value: T) {}
  type = "success" as const;
  isSuccess(): this is Success<T, E> {
    return true;
  }
  isFailure(): this is Failure<T, E> {
    return false;
  }
}

export class Failure<T, E extends Error> {
  constructor(readonly value: E, readonly errorType: ErrorType) {}
  type = "failure" as const;
  isSuccess(): this is Success<T, E> {
    return false;
  }
  isFailure(): this is Failure<T, E> {
    return true;
  }
  isBusinessError(): boolean {
    return this.errorType === "business";
  }
  isSystemError(): boolean {
    return this.errorType === "system";
  }
}
```
#### 気になる点
特定のエラーをthrowしないような関数を実装する場合、  
上記の実装ではResult型を指定する際にエラー型も必ず指定しないといけない作りになっているため  
Error型をextendsしたNoErrorDefinedをそういった場合用に作成しているが、  
エラーじゃないのにError型をextendsしていて気持ち悪い感じがする

### ③想定外のエラー発生時、エラーレスポンスを返す

#### APIごとに記述しなくて良いようにする
⇒①で記述した通り、catchしたときにエラーレスポンスを返すよう実装

#### エラーを想定内エラー（業務エラー）と想定外エラー（システムエラー）に分けレスポンスを変える
⇒Failure型のコンストラクタの引数にErrorTypeを指定し、
　業務エラーかシステムエラーかインスタンス生成時に指定するようにする。
　さらにラッピング関数で業務エラーかシステムエラーかチェックし  
　レスポンスを分岐させる。

``` typescript
export function resultToResponse<T, E extends Error>(
  handler: (request: NextRequest) => Promise<Result<T, E>>
): (request: NextRequest) => Promise<NextResponse> {
  return async (request: NextRequest) => {
    const result = await handler(request);
    // 成功の場合
    if (result.isSuccess()) {
      return NextResponse.json(result.value);
    } else {
      if (result.isBusinessError()) {
        // 業務エラーの場合
        return NextResponse.json(
          {
            error: result.value.message,
          },
          { status: 400 }
        );
      } else {
        return NextResponse.json(
          {
            error: "システムエラーが発生しました",
          },
          { status: 500 }
        );
      }
    }
  };
}
```
#### 気になる点
authenticateでもcatchで500エラーを返すよう記述し、  
resultToResponseでも500エラーを返すよう記述していて重複しているのが気持ち悪い。  
※想定していないエラーが発生した場合を想定し、  
　最上位のラッピング関数のauthenticateのcatchで500エラーを返すように指定している
